[2025-08-13T12:22:16.654+0000] {taskinstance.py:1159} INFO - Dependencies all met for dep_context=non-requeueable deps ti=<TaskInstance: weather_etl_pipeline.transform_data manual__2025-08-13T12:22:12.059300+00:00 [queued]>
[2025-08-13T12:22:16.674+0000] {taskinstance.py:1159} INFO - Dependencies all met for dep_context=requeueable deps ti=<TaskInstance: weather_etl_pipeline.transform_data manual__2025-08-13T12:22:12.059300+00:00 [queued]>
[2025-08-13T12:22:16.676+0000] {taskinstance.py:1361} INFO - Starting attempt 1 of 1
[2025-08-13T12:22:16.704+0000] {taskinstance.py:1382} INFO - Executing <Task(PythonOperator): transform_data> on 2025-08-13 12:22:12.059300+00:00
[2025-08-13T12:22:16.711+0000] {standard_task_runner.py:57} INFO - Started process 479 to run task
[2025-08-13T12:22:16.719+0000] {standard_task_runner.py:84} INFO - Running: ['***', 'tasks', 'run', 'weather_etl_pipeline', 'transform_data', 'manual__2025-08-13T12:22:12.059300+00:00', '--job-id', '21', '--raw', '--subdir', 'DAGS_FOLDER/weather_etl.py', '--cfg-path', '/tmp/tmpmooto1z_']
[2025-08-13T12:22:16.725+0000] {standard_task_runner.py:85} INFO - Job 21: Subtask transform_data
[2025-08-13T12:22:16.780+0000] {logging_mixin.py:151} WARNING - /home/***/.local/lib/python3.8/site-packages/***/settings.py:193 DeprecationWarning: The sql_alchemy_conn option in [core] has been moved to the sql_alchemy_conn option in [database] - the old setting has been used, but please update your config.
[2025-08-13T12:22:16.853+0000] {task_command.py:416} INFO - Running <TaskInstance: weather_etl_pipeline.transform_data manual__2025-08-13T12:22:12.059300+00:00 [running]> on host 1d02f9b6d307
[2025-08-13T12:22:16.985+0000] {taskinstance.py:1662} INFO - Exporting env vars: AIRFLOW_CTX_DAG_OWNER='***' AIRFLOW_CTX_DAG_ID='weather_etl_pipeline' AIRFLOW_CTX_TASK_ID='transform_data' AIRFLOW_CTX_EXECUTION_DATE='2025-08-13T12:22:12.059300+00:00' AIRFLOW_CTX_TRY_NUMBER='1' AIRFLOW_CTX_DAG_RUN_ID='manual__2025-08-13T12:22:12.059300+00:00'
[2025-08-13T12:22:16.991+0000] {logging_mixin.py:151} INFO - Error transforming CSV: [Errno 2] No such file or directory: '/tmp/weather_data_extracted.csv'
[2025-08-13T12:22:16.992+0000] {python.py:194} INFO - Done. Returned value was: None
[2025-08-13T12:22:17.008+0000] {taskinstance.py:1400} INFO - Marking task as SUCCESS. dag_id=weather_etl_pipeline, task_id=transform_data, execution_date=20250813T122212, start_date=20250813T122216, end_date=20250813T122217
[2025-08-13T12:22:17.064+0000] {local_task_job_runner.py:228} INFO - Task exited with return code 0
[2025-08-13T12:22:17.097+0000] {taskinstance.py:2778} INFO - 1 downstream tasks scheduled from follow-on schedule check
