[2025-08-13T12:10:09.039+0000] {taskinstance.py:1159} INFO - Dependencies all met for dep_context=non-requeueable deps ti=<TaskInstance: weather_etl_pipeline.transform_data manual__2025-08-13T12:10:05.466357+00:00 [queued]>
[2025-08-13T12:10:09.056+0000] {taskinstance.py:1159} INFO - Dependencies all met for dep_context=requeueable deps ti=<TaskInstance: weather_etl_pipeline.transform_data manual__2025-08-13T12:10:05.466357+00:00 [queued]>
[2025-08-13T12:10:09.057+0000] {taskinstance.py:1361} INFO - Starting attempt 1 of 1
[2025-08-13T12:10:09.076+0000] {taskinstance.py:1382} INFO - Executing <Task(PythonOperator): transform_data> on 2025-08-13 12:10:05.466357+00:00
[2025-08-13T12:10:09.083+0000] {standard_task_runner.py:57} INFO - Started process 327 to run task
[2025-08-13T12:10:09.090+0000] {standard_task_runner.py:84} INFO - Running: ['***', 'tasks', 'run', 'weather_etl_pipeline', 'transform_data', 'manual__2025-08-13T12:10:05.466357+00:00', '--job-id', '16', '--raw', '--subdir', 'DAGS_FOLDER/weather_etl.py', '--cfg-path', '/tmp/tmpiy_2r2e5']
[2025-08-13T12:10:09.094+0000] {standard_task_runner.py:85} INFO - Job 16: Subtask transform_data
[2025-08-13T12:10:09.121+0000] {logging_mixin.py:151} WARNING - /home/***/.local/lib/python3.8/site-packages/***/settings.py:193 DeprecationWarning: The sql_alchemy_conn option in [core] has been moved to the sql_alchemy_conn option in [database] - the old setting has been used, but please update your config.
[2025-08-13T12:10:09.167+0000] {task_command.py:416} INFO - Running <TaskInstance: weather_etl_pipeline.transform_data manual__2025-08-13T12:10:05.466357+00:00 [running]> on host 1d02f9b6d307
[2025-08-13T12:10:09.327+0000] {taskinstance.py:1662} INFO - Exporting env vars: AIRFLOW_CTX_DAG_OWNER='***' AIRFLOW_CTX_DAG_ID='weather_etl_pipeline' AIRFLOW_CTX_TASK_ID='transform_data' AIRFLOW_CTX_EXECUTION_DATE='2025-08-13T12:10:05.466357+00:00' AIRFLOW_CTX_TRY_NUMBER='1' AIRFLOW_CTX_DAG_RUN_ID='manual__2025-08-13T12:10:05.466357+00:00'
[2025-08-13T12:10:09.328+0000] {taskinstance.py:1937} ERROR - Task failed with exception
Traceback (most recent call last):
  File "/home/airflow/.local/lib/python3.8/site-packages/airflow/operators/python.py", line 192, in execute
    return_value = self.execute_callable()
  File "/home/airflow/.local/lib/python3.8/site-packages/airflow/operators/python.py", line 209, in execute_callable
    return self.python_callable(*self.op_args, **self.op_kwargs)
  File "/opt/airflow/plugins/helpers/weather_etl_utils.py", line 17, in transform_weather_data
    if df.shape[0] == 0:
AttributeError: 'str' object has no attribute 'shape'
[2025-08-13T12:10:09.341+0000] {taskinstance.py:1400} INFO - Marking task as FAILED. dag_id=weather_etl_pipeline, task_id=transform_data, execution_date=20250813T121005, start_date=20250813T121009, end_date=20250813T121009
[2025-08-13T12:10:09.358+0000] {standard_task_runner.py:104} ERROR - Failed to execute job 16 for task transform_data ('str' object has no attribute 'shape'; 327)
[2025-08-13T12:10:09.392+0000] {local_task_job_runner.py:228} INFO - Task exited with return code 1
[2025-08-13T12:10:09.491+0000] {taskinstance.py:2778} INFO - 0 downstream tasks scheduled from follow-on schedule check
