[2025-08-13T11:34:47.403+0000] {taskinstance.py:1159} INFO - Dependencies all met for dep_context=non-requeueable deps ti=<TaskInstance: weather_etl_pipeline.transform_data scheduled__2025-08-13T10:00:00+00:00 [queued]>
[2025-08-13T11:34:47.417+0000] {taskinstance.py:1159} INFO - Dependencies all met for dep_context=requeueable deps ti=<TaskInstance: weather_etl_pipeline.transform_data scheduled__2025-08-13T10:00:00+00:00 [queued]>
[2025-08-13T11:34:47.418+0000] {taskinstance.py:1361} INFO - Starting attempt 2 of 2
[2025-08-13T11:34:47.435+0000] {taskinstance.py:1382} INFO - Executing <Task(PythonOperator): transform_data> on 2025-08-13 10:00:00+00:00
[2025-08-13T11:34:47.443+0000] {standard_task_runner.py:57} INFO - Started process 313 to run task
[2025-08-13T11:34:47.450+0000] {standard_task_runner.py:84} INFO - Running: ['***', 'tasks', 'run', 'weather_etl_pipeline', 'transform_data', 'scheduled__2025-08-13T10:00:00+00:00', '--job-id', '6', '--raw', '--subdir', 'DAGS_FOLDER/weather_etl.py', '--cfg-path', '/tmp/tmp4e6lsoq5']
[2025-08-13T11:34:47.455+0000] {standard_task_runner.py:85} INFO - Job 6: Subtask transform_data
[2025-08-13T11:34:47.586+0000] {task_command.py:416} INFO - Running <TaskInstance: weather_etl_pipeline.transform_data scheduled__2025-08-13T10:00:00+00:00 [running]> on host b3bf99b908a3
[2025-08-13T11:34:47.860+0000] {taskinstance.py:1662} INFO - Exporting env vars: AIRFLOW_CTX_DAG_OWNER='***' AIRFLOW_CTX_DAG_ID='weather_etl_pipeline' AIRFLOW_CTX_TASK_ID='transform_data' AIRFLOW_CTX_EXECUTION_DATE='2025-08-13T10:00:00+00:00' AIRFLOW_CTX_TRY_NUMBER='2' AIRFLOW_CTX_DAG_RUN_ID='scheduled__2025-08-13T10:00:00+00:00'
[2025-08-13T11:34:47.862+0000] {taskinstance.py:1937} ERROR - Task failed with exception
Traceback (most recent call last):
  File "/home/airflow/.local/lib/python3.8/site-packages/airflow/operators/python.py", line 192, in execute
    return_value = self.execute_callable()
  File "/home/airflow/.local/lib/python3.8/site-packages/airflow/operators/python.py", line 209, in execute_callable
    return self.python_callable(*self.op_args, **self.op_kwargs)
  File "/opt/airflow/plugins/helpers/weather_etl_utils.py", line 42, in transform_weather_data
    df[numeric_cols] = df[numeric_cols].apply(pd.to_numeric, errors='coerce')
TypeError: string indices must be integers
[2025-08-13T11:34:47.906+0000] {taskinstance.py:1400} INFO - Marking task as FAILED. dag_id=weather_etl_pipeline, task_id=transform_data, execution_date=20250813T100000, start_date=20250813T113447, end_date=20250813T113447
[2025-08-13T11:34:47.973+0000] {standard_task_runner.py:104} ERROR - Failed to execute job 6 for task transform_data (string indices must be integers; 313)
[2025-08-13T11:34:48.053+0000] {local_task_job_runner.py:228} INFO - Task exited with return code 1
[2025-08-13T11:34:48.114+0000] {taskinstance.py:2778} INFO - 0 downstream tasks scheduled from follow-on schedule check
