[2025-08-13T12:22:18.053+0000] {taskinstance.py:1159} INFO - Dependencies all met for dep_context=non-requeueable deps ti=<TaskInstance: weather_etl_pipeline.load_data manual__2025-08-13T12:22:12.059300+00:00 [queued]>
[2025-08-13T12:22:18.077+0000] {taskinstance.py:1159} INFO - Dependencies all met for dep_context=requeueable deps ti=<TaskInstance: weather_etl_pipeline.load_data manual__2025-08-13T12:22:12.059300+00:00 [queued]>
[2025-08-13T12:22:18.080+0000] {taskinstance.py:1361} INFO - Starting attempt 1 of 1
[2025-08-13T12:22:18.141+0000] {taskinstance.py:1382} INFO - Executing <Task(PythonOperator): load_data> on 2025-08-13 12:22:12.059300+00:00
[2025-08-13T12:22:18.161+0000] {standard_task_runner.py:57} INFO - Started process 481 to run task
[2025-08-13T12:22:18.186+0000] {standard_task_runner.py:84} INFO - Running: ['***', 'tasks', 'run', 'weather_etl_pipeline', 'load_data', 'manual__2025-08-13T12:22:12.059300+00:00', '--job-id', '22', '--raw', '--subdir', 'DAGS_FOLDER/weather_etl.py', '--cfg-path', '/tmp/tmpkfmgcqho']
[2025-08-13T12:22:18.201+0000] {standard_task_runner.py:85} INFO - Job 22: Subtask load_data
[2025-08-13T12:22:18.263+0000] {logging_mixin.py:151} WARNING - /home/***/.local/lib/python3.8/site-packages/***/settings.py:193 DeprecationWarning: The sql_alchemy_conn option in [core] has been moved to the sql_alchemy_conn option in [database] - the old setting has been used, but please update your config.
[2025-08-13T12:22:18.332+0000] {task_command.py:416} INFO - Running <TaskInstance: weather_etl_pipeline.load_data manual__2025-08-13T12:22:12.059300+00:00 [running]> on host 1d02f9b6d307
[2025-08-13T12:22:18.462+0000] {taskinstance.py:1662} INFO - Exporting env vars: AIRFLOW_CTX_DAG_OWNER='***' AIRFLOW_CTX_DAG_ID='weather_etl_pipeline' AIRFLOW_CTX_TASK_ID='load_data' AIRFLOW_CTX_EXECUTION_DATE='2025-08-13T12:22:12.059300+00:00' AIRFLOW_CTX_TRY_NUMBER='1' AIRFLOW_CTX_DAG_RUN_ID='manual__2025-08-13T12:22:12.059300+00:00'
[2025-08-13T12:22:18.468+0000] {taskinstance.py:1937} ERROR - Task failed with exception
Traceback (most recent call last):
  File "/home/airflow/.local/lib/python3.8/site-packages/airflow/operators/python.py", line 192, in execute
    return_value = self.execute_callable()
  File "/home/airflow/.local/lib/python3.8/site-packages/airflow/operators/python.py", line 209, in execute_callable
    return self.python_callable(*self.op_args, **self.op_kwargs)
  File "/opt/airflow/dags/weather_etl.py", line 30, in load_data_to_postgres
    df = pd.read_csv(TRANSFORM_TMP)
  File "/home/airflow/.local/lib/python3.8/site-packages/pandas/io/parsers/readers.py", line 912, in read_csv
    return _read(filepath_or_buffer, kwds)
  File "/home/airflow/.local/lib/python3.8/site-packages/pandas/io/parsers/readers.py", line 577, in _read
    parser = TextFileReader(filepath_or_buffer, **kwds)
  File "/home/airflow/.local/lib/python3.8/site-packages/pandas/io/parsers/readers.py", line 1407, in __init__
    self._engine = self._make_engine(f, self.engine)
  File "/home/airflow/.local/lib/python3.8/site-packages/pandas/io/parsers/readers.py", line 1661, in _make_engine
    self.handles = get_handle(
  File "/home/airflow/.local/lib/python3.8/site-packages/pandas/io/common.py", line 859, in get_handle
    handle = open(
FileNotFoundError: [Errno 2] No such file or directory: '/tmp/weather_data_transformed.csv'
[2025-08-13T12:22:18.484+0000] {taskinstance.py:1400} INFO - Marking task as FAILED. dag_id=weather_etl_pipeline, task_id=load_data, execution_date=20250813T122212, start_date=20250813T122218, end_date=20250813T122218
[2025-08-13T12:22:18.504+0000] {standard_task_runner.py:104} ERROR - Failed to execute job 22 for task load_data ([Errno 2] No such file or directory: '/tmp/weather_data_transformed.csv'; 481)
[2025-08-13T12:22:18.539+0000] {local_task_job_runner.py:228} INFO - Task exited with return code 1
[2025-08-13T12:22:18.566+0000] {taskinstance.py:2778} INFO - 0 downstream tasks scheduled from follow-on schedule check
