[2025-08-13T12:16:31.762+0000] {taskinstance.py:1159} INFO - Dependencies all met for dep_context=non-requeueable deps ti=<TaskInstance: weather_etl_pipeline.extract_data scheduled__2025-08-13T11:00:00+00:00 [queued]>
[2025-08-13T12:16:31.775+0000] {taskinstance.py:1159} INFO - Dependencies all met for dep_context=requeueable deps ti=<TaskInstance: weather_etl_pipeline.extract_data scheduled__2025-08-13T11:00:00+00:00 [queued]>
[2025-08-13T12:16:31.776+0000] {taskinstance.py:1361} INFO - Starting attempt 1 of 1
[2025-08-13T12:16:31.805+0000] {taskinstance.py:1382} INFO - Executing <Task(PythonOperator): extract_data> on 2025-08-13 11:00:00+00:00
[2025-08-13T12:16:31.813+0000] {standard_task_runner.py:57} INFO - Started process 403 to run task
[2025-08-13T12:16:31.821+0000] {standard_task_runner.py:84} INFO - Running: ['***', 'tasks', 'run', 'weather_etl_pipeline', 'extract_data', 'scheduled__2025-08-13T11:00:00+00:00', '--job-id', '17', '--raw', '--subdir', 'DAGS_FOLDER/weather_etl.py', '--cfg-path', '/tmp/tmpaw43hfj6']
[2025-08-13T12:16:31.825+0000] {standard_task_runner.py:85} INFO - Job 17: Subtask extract_data
[2025-08-13T12:16:31.855+0000] {logging_mixin.py:151} WARNING - /home/***/.local/lib/python3.8/site-packages/***/settings.py:193 DeprecationWarning: The sql_alchemy_conn option in [core] has been moved to the sql_alchemy_conn option in [database] - the old setting has been used, but please update your config.
[2025-08-13T12:16:31.903+0000] {task_command.py:416} INFO - Running <TaskInstance: weather_etl_pipeline.extract_data scheduled__2025-08-13T11:00:00+00:00 [running]> on host 1d02f9b6d307
[2025-08-13T12:16:32.051+0000] {taskinstance.py:1662} INFO - Exporting env vars: AIRFLOW_CTX_DAG_OWNER='***' AIRFLOW_CTX_DAG_ID='weather_etl_pipeline' AIRFLOW_CTX_TASK_ID='extract_data' AIRFLOW_CTX_EXECUTION_DATE='2025-08-13T11:00:00+00:00' AIRFLOW_CTX_TRY_NUMBER='1' AIRFLOW_CTX_DAG_RUN_ID='scheduled__2025-08-13T11:00:00+00:00'
[2025-08-13T12:16:32.055+0000] {taskinstance.py:1937} ERROR - Task failed with exception
Traceback (most recent call last):
  File "/home/airflow/.local/lib/python3.8/site-packages/airflow/operators/python.py", line 192, in execute
    return_value = self.execute_callable()
  File "/home/airflow/.local/lib/python3.8/site-packages/airflow/operators/python.py", line 209, in execute_callable
    return self.python_callable(*self.op_args, **self.op_kwargs)
TypeError: extract_weather_data() missing 1 required positional argument: 'csv_path'
[2025-08-13T12:16:32.075+0000] {taskinstance.py:1400} INFO - Marking task as FAILED. dag_id=weather_etl_pipeline, task_id=extract_data, execution_date=20250813T110000, start_date=20250813T121631, end_date=20250813T121632
[2025-08-13T12:16:32.100+0000] {standard_task_runner.py:104} ERROR - Failed to execute job 17 for task extract_data (extract_weather_data() missing 1 required positional argument: 'csv_path'; 403)
[2025-08-13T12:16:32.123+0000] {local_task_job_runner.py:228} INFO - Task exited with return code 1
[2025-08-13T12:16:32.161+0000] {taskinstance.py:2778} INFO - 0 downstream tasks scheduled from follow-on schedule check
