[2025-08-13T11:39:51.528+0000] {taskinstance.py:1159} INFO - Dependencies all met for dep_context=non-requeueable deps ti=<TaskInstance: weather_etl_pipeline.transform_data manual__2025-08-13T11:39:45.054678+00:00 [queued]>
[2025-08-13T11:39:51.543+0000] {taskinstance.py:1159} INFO - Dependencies all met for dep_context=requeueable deps ti=<TaskInstance: weather_etl_pipeline.transform_data manual__2025-08-13T11:39:45.054678+00:00 [queued]>
[2025-08-13T11:39:51.544+0000] {taskinstance.py:1361} INFO - Starting attempt 1 of 2
[2025-08-13T11:39:51.569+0000] {taskinstance.py:1382} INFO - Executing <Task(PythonOperator): transform_data> on 2025-08-13 11:39:45.054678+00:00
[2025-08-13T11:39:51.577+0000] {standard_task_runner.py:57} INFO - Started process 186 to run task
[2025-08-13T11:39:51.584+0000] {standard_task_runner.py:84} INFO - Running: ['***', 'tasks', 'run', 'weather_etl_pipeline', 'transform_data', 'manual__2025-08-13T11:39:45.054678+00:00', '--job-id', '10', '--raw', '--subdir', 'DAGS_FOLDER/weather_etl.py', '--cfg-path', '/tmp/tmpt7tqm11l']
[2025-08-13T11:39:51.589+0000] {standard_task_runner.py:85} INFO - Job 10: Subtask transform_data
[2025-08-13T11:39:51.620+0000] {logging_mixin.py:151} WARNING - /home/***/.local/lib/python3.8/site-packages/***/settings.py:193 DeprecationWarning: The sql_alchemy_conn option in [core] has been moved to the sql_alchemy_conn option in [database] - the old setting has been used, but please update your config.
[2025-08-13T11:39:51.674+0000] {task_command.py:416} INFO - Running <TaskInstance: weather_etl_pipeline.transform_data manual__2025-08-13T11:39:45.054678+00:00 [running]> on host 08b9f79dd387
[2025-08-13T11:39:51.984+0000] {taskinstance.py:1662} INFO - Exporting env vars: AIRFLOW_CTX_DAG_OWNER='***' AIRFLOW_CTX_DAG_ID='weather_etl_pipeline' AIRFLOW_CTX_TASK_ID='transform_data' AIRFLOW_CTX_EXECUTION_DATE='2025-08-13T11:39:45.054678+00:00' AIRFLOW_CTX_TRY_NUMBER='1' AIRFLOW_CTX_DAG_RUN_ID='manual__2025-08-13T11:39:45.054678+00:00'
[2025-08-13T11:39:51.988+0000] {taskinstance.py:1937} ERROR - Task failed with exception
Traceback (most recent call last):
  File "/home/airflow/.local/lib/python3.8/site-packages/airflow/operators/python.py", line 192, in execute
    return_value = self.execute_callable()
  File "/home/airflow/.local/lib/python3.8/site-packages/airflow/operators/python.py", line 209, in execute_callable
    return self.python_callable(*self.op_args, **self.op_kwargs)
  File "/opt/airflow/plugins/helpers/weather_etl_utils.py", line 42, in transform_weather_data
    df[numeric_cols] = df[numeric_cols].apply(pd.to_numeric, errors='coerce')
TypeError: string indices must be integers
[2025-08-13T11:39:52.004+0000] {taskinstance.py:1400} INFO - Marking task as UP_FOR_RETRY. dag_id=weather_etl_pipeline, task_id=transform_data, execution_date=20250813T113945, start_date=20250813T113951, end_date=20250813T113952
[2025-08-13T11:39:52.028+0000] {standard_task_runner.py:104} ERROR - Failed to execute job 10 for task transform_data (string indices must be integers; 186)
[2025-08-13T11:39:52.053+0000] {local_task_job_runner.py:228} INFO - Task exited with return code 1
[2025-08-13T11:39:52.097+0000] {taskinstance.py:2778} INFO - 0 downstream tasks scheduled from follow-on schedule check
