[2025-08-13T11:44:53.007+0000] {taskinstance.py:1159} INFO - Dependencies all met for dep_context=non-requeueable deps ti=<TaskInstance: weather_etl_pipeline.transform_data manual__2025-08-13T11:39:45.054678+00:00 [queued]>
[2025-08-13T11:44:53.020+0000] {taskinstance.py:1159} INFO - Dependencies all met for dep_context=requeueable deps ti=<TaskInstance: weather_etl_pipeline.transform_data manual__2025-08-13T11:39:45.054678+00:00 [queued]>
[2025-08-13T11:44:53.021+0000] {taskinstance.py:1361} INFO - Starting attempt 2 of 2
[2025-08-13T11:44:53.056+0000] {taskinstance.py:1382} INFO - Executing <Task(PythonOperator): transform_data> on 2025-08-13 11:39:45.054678+00:00
[2025-08-13T11:44:53.068+0000] {standard_task_runner.py:57} INFO - Started process 239 to run task
[2025-08-13T11:44:53.082+0000] {standard_task_runner.py:84} INFO - Running: ['***', 'tasks', 'run', 'weather_etl_pipeline', 'transform_data', 'manual__2025-08-13T11:39:45.054678+00:00', '--job-id', '11', '--raw', '--subdir', 'DAGS_FOLDER/weather_etl.py', '--cfg-path', '/tmp/tmpkgn9fb08']
[2025-08-13T11:44:53.088+0000] {standard_task_runner.py:85} INFO - Job 11: Subtask transform_data
[2025-08-13T11:44:53.127+0000] {logging_mixin.py:151} WARNING - /home/***/.local/lib/python3.8/site-packages/***/settings.py:193 DeprecationWarning: The sql_alchemy_conn option in [core] has been moved to the sql_alchemy_conn option in [database] - the old setting has been used, but please update your config.
[2025-08-13T11:44:53.240+0000] {task_command.py:416} INFO - Running <TaskInstance: weather_etl_pipeline.transform_data manual__2025-08-13T11:39:45.054678+00:00 [running]> on host 08b9f79dd387
[2025-08-13T11:44:53.461+0000] {taskinstance.py:1662} INFO - Exporting env vars: AIRFLOW_CTX_DAG_OWNER='***' AIRFLOW_CTX_DAG_ID='weather_etl_pipeline' AIRFLOW_CTX_TASK_ID='transform_data' AIRFLOW_CTX_EXECUTION_DATE='2025-08-13T11:39:45.054678+00:00' AIRFLOW_CTX_TRY_NUMBER='2' AIRFLOW_CTX_DAG_RUN_ID='manual__2025-08-13T11:39:45.054678+00:00'
[2025-08-13T11:44:53.467+0000] {taskinstance.py:1937} ERROR - Task failed with exception
Traceback (most recent call last):
  File "/home/airflow/.local/lib/python3.8/site-packages/airflow/operators/python.py", line 192, in execute
    return_value = self.execute_callable()
  File "/home/airflow/.local/lib/python3.8/site-packages/airflow/operators/python.py", line 209, in execute_callable
    return self.python_callable(*self.op_args, **self.op_kwargs)
  File "/opt/airflow/plugins/helpers/weather_etl_utils.py", line 42, in transform_weather_data
    df[numeric_cols] = df[numeric_cols].apply(pd.to_numeric, errors='coerce')
TypeError: string indices must be integers
[2025-08-13T11:44:53.480+0000] {taskinstance.py:1400} INFO - Marking task as FAILED. dag_id=weather_etl_pipeline, task_id=transform_data, execution_date=20250813T113945, start_date=20250813T114453, end_date=20250813T114453
[2025-08-13T11:44:53.502+0000] {standard_task_runner.py:104} ERROR - Failed to execute job 11 for task transform_data (string indices must be integers; 239)
[2025-08-13T11:44:53.550+0000] {local_task_job_runner.py:228} INFO - Task exited with return code 1
[2025-08-13T11:44:53.581+0000] {taskinstance.py:2778} INFO - 0 downstream tasks scheduled from follow-on schedule check
