[2025-08-13T12:32:09.305+0000] {taskinstance.py:1159} INFO - Dependencies all met for dep_context=non-requeueable deps ti=<TaskInstance: weather_etl_pipeline.load_data manual__2025-08-13T12:32:02.962934+00:00 [queued]>
[2025-08-13T12:32:09.319+0000] {taskinstance.py:1159} INFO - Dependencies all met for dep_context=requeueable deps ti=<TaskInstance: weather_etl_pipeline.load_data manual__2025-08-13T12:32:02.962934+00:00 [queued]>
[2025-08-13T12:32:09.320+0000] {taskinstance.py:1361} INFO - Starting attempt 1 of 1
[2025-08-13T12:32:09.342+0000] {taskinstance.py:1382} INFO - Executing <Task(PythonOperator): load_data> on 2025-08-13 12:32:02.962934+00:00
[2025-08-13T12:32:09.350+0000] {standard_task_runner.py:57} INFO - Started process 593 to run task
[2025-08-13T12:32:09.356+0000] {standard_task_runner.py:84} INFO - Running: ['***', 'tasks', 'run', 'weather_etl_pipeline', 'load_data', 'manual__2025-08-13T12:32:02.962934+00:00', '--job-id', '28', '--raw', '--subdir', 'DAGS_FOLDER/weather_etl.py', '--cfg-path', '/tmp/tmpp4hduwfz']
[2025-08-13T12:32:09.361+0000] {standard_task_runner.py:85} INFO - Job 28: Subtask load_data
[2025-08-13T12:32:09.389+0000] {logging_mixin.py:151} WARNING - /home/***/.local/lib/python3.8/site-packages/***/settings.py:193 DeprecationWarning: The sql_alchemy_conn option in [core] has been moved to the sql_alchemy_conn option in [database] - the old setting has been used, but please update your config.
[2025-08-13T12:32:09.436+0000] {task_command.py:416} INFO - Running <TaskInstance: weather_etl_pipeline.load_data manual__2025-08-13T12:32:02.962934+00:00 [running]> on host 1d02f9b6d307
[2025-08-13T12:32:09.564+0000] {taskinstance.py:1662} INFO - Exporting env vars: AIRFLOW_CTX_DAG_OWNER='***' AIRFLOW_CTX_DAG_ID='weather_etl_pipeline' AIRFLOW_CTX_TASK_ID='load_data' AIRFLOW_CTX_EXECUTION_DATE='2025-08-13T12:32:02.962934+00:00' AIRFLOW_CTX_TRY_NUMBER='1' AIRFLOW_CTX_DAG_RUN_ID='manual__2025-08-13T12:32:02.962934+00:00'
[2025-08-13T12:32:09.615+0000] {taskinstance.py:1937} ERROR - Task failed with exception
Traceback (most recent call last):
  File "/home/airflow/.local/lib/python3.8/site-packages/airflow/operators/python.py", line 192, in execute
    return_value = self.execute_callable()
  File "/home/airflow/.local/lib/python3.8/site-packages/airflow/operators/python.py", line 209, in execute_callable
    return self.python_callable(*self.op_args, **self.op_kwargs)
  File "/opt/airflow/dags/weather_etl.py", line 40, in load_data_to_postgres
    conn = pg_hook.get_conn()
  File "/home/airflow/.local/lib/python3.8/site-packages/airflow/providers/postgres/hooks/postgres.py", line 125, in get_conn
    conn = deepcopy(self.connection or self.get_connection(conn_id))
  File "/home/airflow/.local/lib/python3.8/site-packages/airflow/hooks/base.py", line 72, in get_connection
    conn = Connection.get_connection_from_secrets(conn_id)
  File "/home/airflow/.local/lib/python3.8/site-packages/airflow/models/connection.py", line 477, in get_connection_from_secrets
    raise AirflowNotFoundException(f"The conn_id `{conn_id}` isn't defined")
airflow.exceptions.AirflowNotFoundException: The conn_id `postgres_weather` isn't defined
[2025-08-13T12:32:09.623+0000] {taskinstance.py:1400} INFO - Marking task as FAILED. dag_id=weather_etl_pipeline, task_id=load_data, execution_date=20250813T123202, start_date=20250813T123209, end_date=20250813T123209
[2025-08-13T12:32:09.642+0000] {standard_task_runner.py:104} ERROR - Failed to execute job 28 for task load_data (The conn_id `postgres_weather` isn't defined; 593)
[2025-08-13T12:32:09.663+0000] {local_task_job_runner.py:228} INFO - Task exited with return code 1
[2025-08-13T12:32:09.754+0000] {taskinstance.py:2778} INFO - 0 downstream tasks scheduled from follow-on schedule check
